Workbook

Sheet Cleaning_Practice
A2: Source: deterministic synthetic generator, seed 20261016. No employer or customer data.
A4: application_id | B4: submitted_date | C4: channel | D4: branch_id | E4: requested_amount | F4: missing_docs_at_intake | G4: document_ready_date | H4: review_start_date | I4: decision_date | J4: withdrawal_date | K4: status | L4: Clean channel
A5: LA0001 | B5: 46040 | C5: online | D5: DIGITAL | E5: 16000 | F5: 0 | G5: 46042 | H5: 46046 | I5: 46049 | K5: Approved | L5: =PROPER(TRIM(C5)) -> Online
A6: LA0002 | B6: 46035 | C6: online | D6: DIGITAL | E6: 15000 | F6: 0 | G6: 46037 | H6: 46039 | I6: 46042 | K6: Approved | L6: =PROPER(TRIM(C6)) -> Online
A7: LA0003 | B7: 46103 | C7: online | D7: DIGITAL | E7: 43000 | F7: 0 | G7: 46105 | H7: 46106 | I7: 46109 | K7: Approved | L7: =PROPER(TRIM(C7)) -> Online
A8: LA0004 | B8: 46083 | C8: branch | D8: B04 | E8: 12000 | F8: 0 | G8: 46085 | H8: 46088 | I8: 46091 | K8: Approved | L8: =PROPER(TRIM(C8)) -> Branch
A9: LA0005 | B9: 46078 | C9: online | D9: DIGITAL | E9: 6000 | F9: 0 | G9: 46080 | H9: 46085 | I9: 46086 | K9: Approved | L9: =PROPER(TRIM(C9)) -> Online
A10: LA0006 | B10: 46083 | C10: branch | D10: B03 | E10: 38000 | F10: 0 | G10: 46083 | H10: 46087 | I10: 46089 | K10: Declined | L10: =PROPER(TRIM(C10)) -> Branch
A11: LA0007 | B11: 46092 | C11: branch | D11: B01 | E11: 13000 | F11: 0 | G11: 46093 | H11: 46097 | I11: 46099 | K11: Approved | L11: =PROPER(TRIM(C11)) -> Branch
A12: LA0008 | B12: 46038 | C12: branch | D12: B03 | E12: 43000 | F12: 0 | G12: 46040 | H12: 46043 | I12: 46045 | K12: Approved | L12: =PROPER(TRIM(C12)) -> Branch
A13: LA0009 | B13: 46103 | C13: branch | D13: B01 | E13: 29000 | F13: 1 | G13: 46107 | H13: 46110 | I13: 46111 | K13: Declined | L13: =PROPER(TRIM(C13)) -> Branch
A14: LA0010 | B14: 46110 | C14: online | D14: DIGITAL | E14: 12000 | F14: 0 | G14: 46110 | K14: Open | L14: =PROPER(TRIM(C14)) -> Online
A15: LA0011 | B15: 46046 | C15: branch | D15: B02 | E15: 33000 | F15: 1 | G15: 46056 | H15: 46057 | I15: 46058 | K15: Declined | L15: =PROPER(TRIM(C15)) -> Branch
A16: LA0012 | B16: 46100 | C16: branch | D16: B04 | E16: 30000 | F16: 0 | G16: 46100 | H16: 46104 | I16: 46106 | K16: Declined | L16: =PROPER(TRIM(C16)) -> Branch
A17: LA0013 | B17: 46078 | C17: branch | D17: B03 | E17: 30000 | F17: 0 | G17: 46080 | H17: 46086 | I17: 46087 | K17: Approved | L17: =PROPER(TRIM(C17)) -> Branch
A18: LA0014 | B18: 46074 | C18: online | D18: DIGITAL | E18: 20000 | F18: 0 | G18: 46075 | H18: 46081 | I18: 46082 | K18: Declined | L18: =PROPER(TRIM(C18)) -> Online
A19: LA0015 | B19: 46049 | C19: online | D19: DIGITAL | E19: 18000 | F19: 0 | G19: 46050 | H19: 46051 | I19: 46052 | K19: Approved | L19: =PROPER(TRIM(C19)) -> Online
A20: LA0016 | B20: 46090 | C20: online | D20: DIGITAL | E20: 16000 | F20: 0 | G20: 46092 | H20: 46097 | I20: 46100 | K20: Approved | L20: =PROPER(TRIM(C20)) -> Online
A21: LA0017 | B21: 46078 | C21: online | D21: DIGITAL | E21: 17000 | F21: 0 | G21: 46078 | H21: 46082 | I21: 46083 | K21: Approved | L21: =PROPER(TRIM(C21)) -> Online
A22: LA0018 | B22: 46036 | C22: branch | D22: B03 | E22: 33000 | F22: 0 | G22: 46038 | H22: 46046 | I22: 46049 | K22: Approved | L22: =PROPER(TRIM(C22)) -> Branch
A23: LA0019 | B23: 46031 | C23: Online | D23: DIGITAL | E23: 32000 | F23: 1 | G23: 46039 | H23: 46045 | I23: 46047 | K23: Approved | L23: =PROPER(TRIM(C23)) -> Online
A24: LA0020 | B24: 46093 | C24: Branch | D24: B04 | E24: 5000 | F24: 0 | G24: 46095 | H24: 46097 | I24: 46100 | K24: Approved | L24: =PROPER(TRIM(C24)) -> Branch
A25: LA0021 | B25: 46106 | C25: Branch | D25: B02 | E25: 28000 | F25: 0 | G25: 46107 | H25: 46110 | K25: Open | L25: =PROPER(TRIM(C25)) -> Branch
A26: LA0022 | B26: 46079 | C26: Online | D26: DIGITAL | E26: 44000 | F26: 0 | G26: 46081 | H26: 46083 | I26: 46085 | K26: Declined | L26: =PROPER(TRIM(C26)) -> Online
A27: LA0023 | B27: 46101 | C27: Branch | D27: B04 | E27: 6000 | F27: 0 | G27: 46101 | H27: 46105 | I27: 46108 | K27: Approved | L27: =PROPER(TRIM(C27)) -> Branch
A28: LA0024 | B28: 46072 | C28: Online | D28: DIGITAL | E28: 11000 | F28: 0 | G28: 46073 | H28: 46077 | I28: 46079 | K28: Approved | L28: =PROPER(TRIM(C28)) -> Online
A29: LA0025 | B29: 46069 | C29: Branch | D29: B04 | E29: 29000 | F29: 1 | J29: 46071 | K29: Withdrawn | L29: =PROPER(TRIM(C29)) -> Branch
A30: LA0026 | B30: 46036 | C30: Online | D30: DIGITAL | E30: 46000 | F30: 0 | G30: 46038 | H30: 46039 | I30: 46040 | K30: Approved | L30: =PROPER(TRIM(C30)) -> Online
A31: LA0027 | B31: 46045 | C31: Online | D31: DIGITAL | E31: 12000 | F31: 0 | G31: 46047 | H31: 46053 | I31: 46056 | K31: Declined | L31: =PROPER(TRIM(C31)) -> Online
A32: LA0028 | B32: 46052 | C32: Online | D32: DIGITAL | E32: 27000 | F32: 0 | G32: 46053 | H32: 46055 | I32: 46057 | K32: Declined | L32: =PROPER(TRIM(C32)) -> Online
A33: LA0029 | B33: 46073 | C33: Branch | D33: B01 | E33: 11000 | F33: 1 | G33: 46077 | H33: 46082 | I33: 46085 | K33: Approved | L33: =PROPER(TRIM(C33)) -> Branch
A34: LA0030 | B34: 46073 | C34: Branch | D34: B04 | E34: 31000 | F34: 1 | G34: 46076 | H34: 46080 | I34: 46081 | K34: Approved | L34: =PROPER(TRIM(C34)) -> Branch
A35: LA0031 | B35: 46107 | C35: Online | D35: DIGITAL | E35: 24000 | F35: 0 | G35: 46108 | H35: 46112 | K35: Open | L35: =PROPER(TRIM(C35)) -> Online
A36: LA0032 | B36: 46040 | C36: Online | D36: DIGITAL | E36: 21000 | F36: 0 | G36: 46040 | H36: 46046 | I36: 46049 | K36: Approved | L36: =PROPER(TRIM(C36)) -> Online
A37: LA0033 | B37: 46057 | C37: Online | D37: DIGITAL | E37: 14000 | F37: 0 | G37: 46059 | H37: 46062 | I37: 46065 | K37: Declined | L37: =PROPER(TRIM(C37)) -> Online
A38: LA0034 | B38: 46090 | C38: Online | D38: DIGITAL | E38: 16000 | F38: 0 | G38: 46090 | H38: 46094 | I38: 46097 | K38: Approved | L38: =PROPER(TRIM(C38)) -> Online
A39: LA0035 | B39: 46112 | C39: Online | D39: DIGITAL | E39: 23000 | F39: 0 | G39: 46112 | K39: Open | L39: =PROPER(TRIM(C39)) -> Online
A40: LA0036 | B40: 46093 | C40: Online | D40: DIGITAL | E40: 28000 | F40: 0 | G40: 46094 | H40: 46097 | I40: 46098 | K40: Declined | L40: =PROPER(TRIM(C40)) -> Online
A41: LA0037 | B41: 46043 | C41: Online | D41: DIGITAL | E41: 14000 | F41: 1 | G41: 46051 | H41: 46054 | I41: 46055 | K41: Approved | L41: =PROPER(TRIM(C41)) -> Online
A42: LA0038 | B42: 46030 | C42: Branch | D42: B02 | E42: 35000 | F42: 1 | J42: 46032 | K42: Withdrawn | L42: =PROPER(TRIM(C42)) -> Branch
...

Sheet Gap_Analysis
A1: Finding | B1: Current situation | C1: Desired situation | D1: Proposed action
A2: Missing documents | B2: Average decision time: 12.20 days with missing documents versus 6.97 without. | C2: Customers know the required documents and officers identify missing items early. | D2: Add an intake checklist and check completeness before review.
A3: Review queue | B3: Average queue: 3.92 days overall. B03: 5.68 days. | C3: Applications ready for review have clear owners and visible waiting times. | D3: Add a shared queue with assigned owners. Investigate B03 staffing, routing, and workload.
A4: Aging applications | B4: 8 of 61 open applications exceeded 7 days as of March 31, 2026. | C4: Staff can identify applications needing follow up. | D4: Flag open applications older than 7 days and assign a follow up owner.

Sheet Summary
A2: Banking loan application process
A3: Fictional bank. Synthetic applications submitted January to March 2026. Snapshot: March 31, 2026.
A5: Decision target (calendar days) | B5: 7 | D5: The 7 day target is a project assumption, not a regulatory deadline.
A6: Snapshot date | B6: 46112
A8: Measure | B8: Baseline
A9: Applications | B9: =COUNTA(Applications!$A$5:$A$604) -> 600
A10: Decisioned applications | B10: =SUM(Applications!$L$5:$L$604) -> 505
A11: Open applications | B11: =COUNTIFS(Applications!$K$5:$K$604,"Open") -> 61
A12: Withdrawn applications | B12: =COUNTIFS(Applications!$K$5:$K$604,"Withdrawn") -> 34
A13: Missing documents at intake | B13: =AVERAGE(Applications!$F$5:$F$604) -> 0.34833333
A14: Mean decision days | B14: =AVERAGE(Applications!$M$5:$M$604) -> 8.5425743
A15: Within decision target | B15: =AVERAGE(Applications!$R$5:$R$604) -> 0.42970297
A16: Approval rate of decisions | B16: =COUNTIFS(Applications!$K$5:$K$604,"Approved")/B10 -> 0.72475248
A17: Open cases over target | B17: =COUNTIFS(Applications!$K$5:$K$604,"Open",Applications!$Q$5:$Q$604,">"&B5) -> 8
A20: Channel | B20: Applications | C20: Decisioned | D20: Mean decision days
A21: Branch | B21: =COUNTIFS(Applications!$C$5:$C$604,A21) -> 331 | C21: =SUMIFS(Applications!$L$5:$L$604,Applications!$C$5:$C$604,A21) -> 281 | D21: =SUMIFS(Applications!$M$5:$M$604,Applications!$C$5:$C$604,A21)/C21 -> 9.1352313
A22: Online | B22: =COUNTIFS(Applications!$C$5:$C$604,A22) -> 269 | C22: =SUMIFS(Applications!$L$5:$L$604,Applications!$C$5:$C$604,A22) -> 224 | D22: =SUMIFS(Applications!$M$5:$M$604,Applications!$C$5:$C$604,A22)/C22 -> 7.7991071
A25: Stage | B25: Mean calendar days
A26: Document collection | B26: =AVERAGE(Applications!$N$5:$N$604) -> 2.6059406 | F26: Stage averages use the same 505 decisioned cases. Elapsed time includes waiting and is not staff labor time.
A27: Review queue | B27: =AVERAGE(Applications!$O$5:$O$604) -> 3.9207921
A28: Review to decision | B28: =AVERAGE(Applications!$P$5:$P$604) -> 2.0158416
A31: Intake documents | B31: Applications | C31: Decisioned | D31: Mean decision days | F31: Synthetic associations reflect the generator assumptions. They are not evidence about any real bank or proof of causation.
A32: Complete at intake | B32: =COUNTIFS(Applications!$F$5:$F$604,0) -> 391 | C32: =SUMIFS(Applications!$L$5:$L$604,Applications!$F$5:$F$604,0) -> 353 | D32: =SUMIFS(Applications!$M$5:$M$604,Applications!$F$5:$F$604,0)/C32 -> 6.9660057
A33: Missing at intake | B33: =COUNTIFS(Applications!$F$5:$F$604,1) -> 209 | C33: =SUMIFS(Applications!$L$5:$L$604,Applications!$F$5:$F$604,1) -> 152 | D33: =SUMIFS(Applications!$M$5:$M$604,Applications!$F$5:$F$604,1)/C33 -> 12.203947
A36: Decision times exclude open and withdrawn cases. Open age is reported separately to expose unfinished work.
A38: Refresh: rerun build_data.py and rebuild the workbook. Formulas cover this fixed 600 application snapshot.
A40: Cleaning reconciliation: 612 raw rows, 12 exact duplicates removed, 18 channel labels normalized, 600 unique applications.

Sheet Applications
A2: Clean applications with calculated measures
A4: application_id | B4: submitted_date | C4: channel | D4: branch_id | E4: requested_amount | F4: missing_docs_at_intake | G4: document_ready_date | H4: review_start_date | I4: decision_date | J4: withdrawal_date | K4: status | L4: is_decisioned | M4: decision_days | N4: document_days | O4: queue_days | P4: review_days | Q4: open_age_days | R4: within_target | S4: submission_month
A5: LA0001 | B5: 46040 | C5: Online | D5: DIGITAL | E5: 16000 | F5: 0 | G5: 46042 | H5: 46046 | I5: 46049 | K5: Approved | L5: =IF(OR(K5="Approved",K5="Declined"),1,0) -> 1 | M5: =IF(L5=1,I5-B5,"") -> 9 | N5: =IF(L5=1,G5-B5,"") -> 2 | O5: =IF(L5=1,H5-G5,"") -> 4 | P5: =IF(L5=1,I5-H5,"") -> 3 | Q5: =IF(K5="Open",Summary!$B$6-B5,"") | R5: =IF(L5=1,IF(M5<=Summary!$B$5,1,0),"") -> 0 | S5: =TEXT(B5,"yyyy-mm") -> 2026-01
A6: LA0002 | B6: 46035 | C6: Online | D6: DIGITAL | E6: 15000 | F6: 0 | G6: 46037 | H6: 46039 | I6: 46042 | K6: Approved | L6: =IF(OR(K6="Approved",K6="Declined"),1,0) -> 1 | M6: =IF(L6=1,I6-B6,"") -> 7 | N6: =IF(L6=1,G6-B6,"") -> 2 | O6: =IF(L6=1,H6-G6,"") -> 2 | P6: =IF(L6=1,I6-H6,"") -> 3 | Q6: =IF(K6="Open",Summary!$B$6-B6,"") | R6: =IF(L6=1,IF(M6<=Summary!$B$5,1,0),"") -> 1 | S6: =TEXT(B6,"yyyy-mm") -> 2026-01
A7: LA0003 | B7: 46103 | C7: Online | D7: DIGITAL | E7: 43000 | F7: 0 | G7: 46105 | H7: 46106 | I7: 46109 | K7: Approved | L7: =IF(OR(K7="Approved",K7="Declined"),1,0) -> 1 | M7: =IF(L7=1,I7-B7,"") -> 6 | N7: =IF(L7=1,G7-B7,"") -> 2 | O7: =IF(L7=1,H7-G7,"") -> 1 | P7: =IF(L7=1,I7-H7,"") -> 3 | Q7: =IF(K7="Open",Summary!$B$6-B7,"") | R7: =IF(L7=1,IF(M7<=Summary!$B$5,1,0),"") -> 1 | S7: =TEXT(B7,"yyyy-mm") -> 2026-03
A8: LA0004 | B8: 46083 | C8: Branch | D8: B04 | E8: 12000 | F8: 0 | G8: 46085 | H8: 46088 | I8: 46091 | K8: Approved | L8: =IF(OR(K8="Approved",K8="Declined"),1,0) -> 1 | M8: =IF(L8=1,I8-B8,"") -> 8 | N8: =IF(L8=1,G8-B8,"") -> 2 | O8: =IF(L8=1,H8-G8,"") -> 3 | P8: =IF(L8=1,I8-H8,"") -> 3 | Q8: =IF(K8="Open",Summary!$B$6-B8,"") | R8: =IF(L8=1,IF(M8<=Summary!$B$5,1,0),"") -> 0 | S8: =TEXT(B8,"yyyy-mm") -> 2026-03
A9: LA0005 | B9: 46078 | C9: Online | D9: DIGITAL | E9: 6000 | F9: 0 | G9: 46080 | H9: 46085 | I9: 46086 | K9: Approved | L9: =IF(OR(K9="Approved",K9="Declined"),1,0) -> 1 | M9: =IF(L9=1,I9-B9,"") -> 8 | N9: =IF(L9=1,G9-B9,"") -> 2 | O9: =IF(L9=1,H9-G9,"") -> 5 | P9: =IF(L9=1,I9-H9,"") -> 1 | Q9: =IF(K9="Open",Summary!$B$6-B9,"") | R9: =IF(L9=1,IF(M9<=Summary!$B$5,1,0),"") -> 0 | S9: =TEXT(B9,"yyyy-mm") -> 2026-02
A10: LA0006 | B10: 46083 | C10: Branch | D10: B03 | E10: 38000 | F10: 0 | G10: 46083 | H10: 46087 | I10: 46089 | K10: Declined | L10: =IF(OR(K10="Approved",K10="Declined"),1,0) -> 1 | M10: =IF(L10=1,I10-B10,"") -> 6 | N10: =IF(L10=1,G10-B10,"") -> 0 | O10: =IF(L10=1,H10-G10,"") -> 4 | P10: =IF(L10=1,I10-H10,"") -> 2 | Q10: =IF(K10="Open",Summary!$B$6-B10,"") | R10: =IF(L10=1,IF(M10<=Summary!$B$5,1,0),"") -> 1 | S10: =TEXT(B10,"yyyy-mm") -> 2026-03
A11: LA0007 | B11: 46092 | C11: Branch | D11: B01 | E11: 13000 | F11: 0 | G11: 46093 | H11: 46097 | I11: 46099 | K11: Approved | L11: =IF(OR(K11="Approved",K11="Declined"),1,0) -> 1 | M11: =IF(L11=1,I11-B11,"") -> 7 | N11: =IF(L11=1,G11-B11,"") -> 1 | O11: =IF(L11=1,H11-G11,"") -> 4 | P11: =IF(L11=1,I11-H11,"") -> 2 | Q11: =IF(K11="Open",Summary!$B$6-B11,"") | R11: =IF(L11=1,IF(M11<=Summary!$B$5,1,0),"") -> 1 | S11: =TEXT(B11,"yyyy-mm") -> 2026-03
A12: LA0008 | B12: 46038 | C12: Branch | D12: B03 | E12: 43000 | F12: 0 | G12: 46040 | H12: 46043 | I12: 46045 | K12: Approved | L12: =IF(OR(K12="Approved",K12="Declined"),1,0) -> 1 | M12: =IF(L12=1,I12-B12,"") -> 7 | N12: =IF(L12=1,G12-B12,"") -> 2 | O12: =IF(L12=1,H12-G12,"") -> 3 | P12: =IF(L12=1,I12-H12,"") -> 2 | Q12: =IF(K12="Open",Summary!$B$6-B12,"") | R12: =IF(L12=1,IF(M12<=Summary!$B$5,1,0),"") -> 1 | S12: =TEXT(B12,"yyyy-mm") -> 2026-01
A13: LA0009 | B13: 46103 | C13: Branch | D13: B01 | E13: 29000 | F13: 1 | G13: 46107 | H13: 46110 | I13: 46111 | K13: Declined | L13: =IF(OR(K13="Approved",K13="Declined"),1,0) -> 1 | M13: =IF(L13=1,I13-B13,"") -> 8 | N13: =IF(L13=1,G13-B13,"") -> 4 | O13: =IF(L13=1,H13-G13,"") -> 3 | P13: =IF(L13=1,I13-H13,"") -> 1 | Q13: =IF(K13="Open",Summary!$B$6-B13,"") | R13: =IF(L13=1,IF(M13<=Summary!$B$5,1,0),"") -> 0 | S13: =TEXT(B13,"yyyy-mm") -> 2026-03
A14: LA0010 | B14: 46110 | C14: Online | D14: DIGITAL | E14: 12000 | F14: 0 | G14: 46110 | K14: Open | L14: =IF(OR(K14="Approved",K14="Declined"),1,0) -> 0 | M14: =IF(L14=1,I14-B14,"") | N14: =IF(L14=1,G14-B14,"") | O14: =IF(L14=1,H14-G14,"") | P14: =IF(L14=1,I14-H14,"") | Q14: =IF(K14="Open",Summary!$B$6-B14,"") -> 2 | R14: =IF(L14=1,IF(M14<=Summary!$B$5,1,0),"") | S14: =TEXT(B14,"yyyy-mm") -> 2026-03
A15: LA0011 | B15: 46046 | C15: Branch | D15: B02 | E15: 33000 | F15: 1 | G15: 46056 | H15: 46057 | I15: 46058 | K15: Declined | L15: =IF(OR(K15="Approved",K15="Declined"),1,0) -> 1 | M15: =IF(L15=1,I15-B15,"") -> 12 | N15: =IF(L15=1,G15-B15,"") -> 10 | O15: =IF(L15=1,H15-G15,"") -> 1 | P15: =IF(L15=1,I15-H15,"") -> 1 | Q15: =IF(K15="Open",Summary!$B$6-B15,"") | R15: =IF(L15=1,IF(M15<=Summary!$B$5,1,0),"") -> 0 | S15: =TEXT(B15,"yyyy-mm") -> 2026-01
A16: LA0012 | B16: 46100 | C16: Branch | D16: B04 | E16: 30000 | F16: 0 | G16: 46100 | H16: 46104 | I16: 46106 | K16: Declined | L16: =IF(OR(K16="Approved",K16="Declined"),1,0) -> 1 | M16: =IF(L16=1,I16-B16,"") -> 6 | N16: =IF(L16=1,G16-B16,"") -> 0 | O16: =IF(L16=1,H16-G16,"") -> 4 | P16: =IF(L16=1,I16-H16,"") -> 2 | Q16: =IF(K16="Open",Summary!$B$6-B16,"") | R16: =IF(L16=1,IF(M16<=Summary!$B$5,1,0),"") -> 1 | S16: =TEXT(B16,"yyyy-mm") -> 2026-03
A17: LA0013 | B17: 46078 | C17: Branch | D17: B03 | E17: 30000 | F17: 0 | G17: 46080 | H17: 46086 | I17: 46087 | K17: Approved | L17: =IF(OR(K17="Approved",K17="Declined"),1,0) -> 1 | M17: =IF(L17=1,I17-B17,"") -> 9 | N17: =IF(L17=1,G17-B17,"") -> 2 | O17: =IF(L17=1,H17-G17,"") -> 6 | P17: =IF(L17=1,I17-H17,"") -> 1 | Q17: =IF(K17="Open",Summary!$B$6-B17,"") | R17: =IF(L17=1,IF(M17<=Summary!$B$5,1,0),"") -> 0 | S17: =TEXT(B17,"yyyy-mm") -> 2026-02
A18: LA0014 | B18: 46074 | C18: Online | D18: DIGITAL | E18: 20000 | F18: 0 | G18: 46075 | H18: 46081 | I18: 46082 | K18: Declined | L18: =IF(OR(K18="Approved",K18="Declined"),1,0) -> 1 | M18: =IF(L18=1,I18-B18,"") -> 8 | N18: =IF(L18=1,G18-B18,"") -> 1 | O18: =IF(L18=1,H18-G18,"") -> 6 | P18: =IF(L18=1,I18-H18,"") -> 1 | Q18: =IF(K18="Open",Summary!$B$6-B18,"") | R18: =IF(L18=1,IF(M18<=Summary!$B$5,1,0),"") -> 0 | S18: =TEXT(B18,"yyyy-mm") -> 2026-02
A19: LA0015 | B19: 46049 | C19: Online | D19: DIGITAL | E19: 18000 | F19: 0 | G19: 46050 | H19: 46051 | I19: 46052 | K19: Approved | L19: =IF(OR(K19="Approved",K19="Declined"),1,0) -> 1 | M19: =IF(L19=1,I19-B19,"") -> 3 | N19: =IF(L19=1,G19-B19,"") -> 1 | O19: =IF(L19=1,H19-G19,"") -> 1 | P19: =IF(L19=1,I19-H19,"") -> 1 | Q19: =IF(K19="Open",Summary!$B$6-B19,"") | R19: =IF(L19=1,IF(M19<=Summary!$B$5,1,0),"") -> 1 | S19: =TEXT(B19,"yyyy-mm") -> 2026-01
A20: LA0016 | B20: 46090 | C20: Online | D20: DIGITAL | E20: 16000 | F20: 0 | G20: 46092 | H20: 46097 | I20: 46100 | K20: Approved | L20: =IF(OR(K20="Approved",K20="Declined"),1,0) -> 1 | M20: =IF(L20=1,I20-B20,"") -> 10 | N20: =IF(L20=1,G20-B20,"") -> 2 | O20: =IF(L20=1,H20-G20,"") -> 5 | P20: =IF(L20=1,I20-H20,"") -> 3 | Q20: =IF(K20="Open",Summary!$B$6-B20,"") | R20: =IF(L20=1,IF(M20<=Summary!$B$5,1,0),"") -> 0 | S20: =TEXT(B20,"yyyy-mm") -> 2026-03
A21: LA0017 | B21: 46078 | C21: Online | D21: DIGITAL | E21: 17000 | F21: 0 | G21: 46078 | H21: 46082 | I21: 46083 | K21: Approved | L21: =IF(OR(K21="Approved",K21="Declined"),1,0) -> 1 | M21: =IF(L21=1,I21-B21,"") -> 5 | N21: =IF(L21=1,G21-B21,"") -> 0 | O21: =IF(L21=1,H21-G21,"") -> 4 | P21: =IF(L21=1,I21-H21,"") -> 1 | Q21: =IF(K21="Open",Summary!$B$6-B21,"") | R21: =IF(L21=1,IF(M21<=Summary!$B$5,1,0),"") -> 1 | S21: =TEXT(B21,"yyyy-mm") -> 2026-02
A22: LA0018 | B22: 46036 | C22: Branch | D22: B03 | E22: 33000 | F22: 0 | G22: 46038 | H22: 46046 | I22: 46049 | K22: Approved | L22: =IF(OR(K22="Approved",K22="Declined"),1,0) -> 1 | M22: =IF(L22=1,I22-B22,"") -> 13 | N22: =IF(L22=1,G22-B22,"") -> 2 | O22: =IF(L22=1,H22-G22,"") -> 8 | P22: =IF(L22=1,I22-H22,"") -> 3 | Q22: =IF(K22="Open",Summary!$B$6-B22,"") | R22: =IF(L22=1,IF(M22<=Summary!$B$5,1,0),"") -> 0 | S22: =TEXT(B22,"yyyy-mm") -> 2026-01
A23: LA0019 | B23: 46031 | C23: Online | D23: DIGITAL | E23: 32000 | F23: 1 | G23: 46039 | H23: 46045 | I23: 46047 | K23: Approved | L23: =IF(OR(K23="Approved",K23="Declined"),1,0) -> 1 | M23: =IF(L23=1,I23-B23,"") -> 16 | N23: =IF(L23=1,G23-B23,"") -> 8 | O23: =IF(L23=1,H23-G23,"") -> 6 | P23: =IF(L23=1,I23-H23,"") -> 2 | Q23: =IF(K23="Open",Summary!$B$6-B23,"") | R23: =IF(L23=1,IF(M23<=Summary!$B$5,1,0),"") -> 0 | S23: =TEXT(B23,"yyyy-mm") -> 2026-01
A24: LA0020 | B24: 46093 | C24: Branch | D24: B04 | E24: 5000 | F24: 0 | G24: 46095 | H24: 46097 | I24: 46100 | K24: Approved | L24: =IF(OR(K24="Approved",K24="Declined"),1,0) -> 1 | M24: =IF(L24=1,I24-B24,"") -> 7 | N24: =IF(L24=1,G24-B24,"") -> 2 | O24: =IF(L24=1,H24-G24,"") -> 2 | P24: =IF(L24=1,I24-H24,"") -> 3 | Q24: =IF(K24="Open",Summary!$B$6-B24,"") | R24: =IF(L24=1,IF(M24<=Summary!$B$5,1,0),"") -> 1 | S24: =TEXT(B24,"yyyy-mm") -> 2026-03
A25: LA0021 | B25: 46106 | C25: Branch | D25: B02 | E25: 28000 | F25: 0 | G25: 46107 | H25: 46110 | K25: Open | L25: =IF(OR(K25="Approved",K25="Declined"),1,0) -> 0 | M25: =IF(L25=1,I25-B25,"") | N25: =IF(L25=1,G25-B25,"") | O25: =IF(L25=1,H25-G25,"") | P25: =IF(L25=1,I25-H25,"") | Q25: =IF(K25="Open",Summary!$B$6-B25,"") -> 6 | R25: =IF(L25=1,IF(M25<=Summary!$B$5,1,0),"") | S25: =TEXT(B25,"yyyy-mm") -> 2026-03
A26: LA0022 | B26: 46079 | C26: Online | D26: DIGITAL | E26: 44000 | F26: 0 | G26: 46081 | H26: 46083 | I26: 46085 | K26: Declined | L26: =IF(OR(K26="Approved",K26="Declined"),1,0) -> 1 | M26: =IF(L26=1,I26-B26,"") -> 6 | N26: =IF(L26=1,G26-B26,"") -> 2 | O26: =IF(L26=1,H26-G26,"") -> 2 | P26: =IF(L26=1,I26-H26,"") -> 2 | Q26: =IF(K26="Open",Summary!$B$6-B26,"") | R26: =IF(L26=1,IF(M26<=Summary!$B$5,1,0),"") -> 1 | S26: =TEXT(B26,"yyyy-mm") -> 2026-02
A27: LA0023 | B27: 46101 | C27: Branch | D27: B04 | E27: 6000 | F27: 0 | G27: 46101 | H27: 46105 | I27: 46108 | K27: Approved | L27: =IF(OR(K27="Approved",K27="Declined"),1,0) -> 1 | M27: =IF(L27=1,I27-B27,"") -> 7 | N27: =IF(L27=1,G27-B27,"") -> 0 | O27: =IF(L27=1,H27-G27,"") -> 4 | P27: =IF(L27=1,I27-H27,"") -> 3 | Q27: =IF(K27="Open",Summary!$B$6-B27,"") | R27: =IF(L27=1,IF(M27<=Summary!$B$5,1,0),"") -> 1 | S27: =TEXT(B27,"yyyy-mm") -> 2026-03
A28: LA0024 | B28: 46072 | C28: Online | D28: DIGITAL | E28: 11000 | F28: 0 | G28: 46073 | H28: 46077 | I28: 46079 | K28: Approved | L28: =IF(OR(K28="Approved",K28="Declined"),1,0) -> 1 | M28: =IF(L28=1,I28-B28,"") -> 7 | N28: =IF(L28=1,G28-B28,"") -> 1 | O28: =IF(L28=1,H28-G28,"") -> 4 | P28: =IF(L28=1,I28-H28,"") -> 2 | Q28: =IF(K28="Open",Summary!$B$6-B28,"") | R28: =IF(L28=1,IF(M28<=Summary!$B$5,1,0),"") -> 1 | S28: =TEXT(B28,"yyyy-mm") -> 2026-02
A29: LA0025 | B29: 46069 | C29: Branch | D29: B04 | E29: 29000 | F29: 1 | J29: 46071 | K29: Withdrawn | L29: =IF(OR(K29="Approved",K29="Declined"),1,0) -> 0 | M29: =IF(L29=1,I29-B29,"") | N29: =IF(L29=1,G29-B29,"") | O29: =IF(L29=1,H29-G29,"") | P29: =IF(L29=1,I29-H29,"") | Q29: =IF(K29="Open",Summary!$B$6-B29,"") | R29: =IF(L29=1,IF(M29<=Summary!$B$5,1,0),"") | S29: =TEXT(B29,"yyyy-mm") -> 2026-02
A30: LA0026 | B30: 46036 | C30: Online | D30: DIGITAL | E30: 46000 | F30: 0 | G30: 46038 | H30: 46039 | I30: 46040 | K30: Approved | L30: =IF(OR(K30="Approved",K30="Declined"),1,0) -> 1 | M30: =IF(L30=1,I30-B30,"") -> 4 | N30: =IF(L30=1,G30-B30,"") -> 2 | O30: =IF(L30=1,H30-G30,"") -> 1 | P30: =IF(L30=1,I30-H30,"") -> 1 | Q30: =IF(K30="Open",Summary!$B$6-B30,"") | R30: =IF(L30=1,IF(M30<=Summary!$B$5,1,0),"") -> 1 | S30: =TEXT(B30,"yyyy-mm") -> 2026-01
A31: LA0027 | B31: 46045 | C31: Online | D31: DIGITAL | E31: 12000 | F31: 0 | G31: 46047 | H31: 46053 | I31: 46056 | K31: Declined | L31: =IF(OR(K31="Approved",K31="Declined"),1,0) -> 1 | M31: =IF(L31=1,I31-B31,"") -> 11 | N31: =IF(L31=1,G31-B31,"") -> 2 | O31: =IF(L31=1,H31-G31,"") -> 6 | P31: =IF(L31=1,I31-H31,"") -> 3 | Q31: =IF(K31="Open",Summary!$B$6-B31,"") | R31: =IF(L31=1,IF(M31<=Summary!$B$5,1,0),"") -> 0 | S31: =TEXT(B31,"yyyy-mm") -> 2026-01
A32: LA0028 | B32: 46052 | C32: Online | D32: DIGITAL | E32: 27000 | F32: 0 | G32: 46053 | H32: 46055 | I32: 46057 | K32: Declined | L32: =IF(OR(K32="Approved",K32="Declined"),1,0) -> 1 | M32: =IF(L32=1,I32-B32,"") -> 5 | N32: =IF(L32=1,G32-B32,"") -> 1 | O32: =IF(L32=1,H32-G32,"") -> 2 | P32: =IF(L32=1,I32-H32,"") -> 2 | Q32: =IF(K32="Open",Summary!$B$6-B32,"") | R32: =IF(L32=1,IF(M32<=Summary!$B$5,1,0),"") -> 1 | S32: =TEXT(B32,"yyyy-mm") -> 2026-01
A33: LA0029 | B33: 46073 | C33: Branch | D33: B01 | E33: 11000 | F33: 1 | G33: 46077 | H33: 46082 | I33: 46085 | K33: Approved | L33: =IF(OR(K33="Approved",K33="Declined"),1,0) -> 1 | M33: =IF(L33=1,I33-B33,"") -> 12 | N33: =IF(L33=1,G33-B33,"") -> 4 | O33: =IF(L33=1,H33-G33,"") -> 5 | P33: =IF(L33=1,I33-H33,"") -> 3 | Q33: =IF(K33="Open",Summary!$B$6-B33,"") | R33: =IF(L33=1,IF(M33<=Summary!$B$5,1,0),"") -> 0 | S33: =TEXT(B33,"yyyy-mm") -> 2026-02
A34: LA0030 | B34: 46073 | C34: Branch | D34: B04 | E34: 31000 | F34: 1 | G34: 46076 | H34: 46080 | I34: 46081 | K34: Approved | L34: =IF(OR(K34="Approved",K34="Declined"),1,0) -> 1 | M34: =IF(L34=1,I34-B34,"") -> 8 | N34: =IF(L34=1,G34-B34,"") -> 3 | O34: =IF(L34=1,H34-G34,"") -> 4 | P34: =IF(L34=1,I34-H34,"") -> 1 | Q34: =IF(K34="Open",Summary!$B$6-B34,"") | R34: =IF(L34=1,IF(M34<=Summary!$B$5,1,0),"") -> 0 | S34: =TEXT(B34,"yyyy-mm") -> 2026-02
A35: LA0031 | B35: 46107 | C35: Online | D35: DIGITAL | E35: 24000 | F35: 0 | G35: 46108 | H35: 46112 | K35: Open | L35: =IF(OR(K35="Approved",K35="Declined"),1,0) -> 0 | M35: =IF(L35=1,I35-B35,"") | N35: =IF(L35=1,G35-B35,"") | O35: =IF(L35=1,H35-G35,"") | P35: =IF(L35=1,I35-H35,"") | Q35: =IF(K35="Open",Summary!$B$6-B35,"") -> 5 | R35: =IF(L35=1,IF(M35<=Summary!$B$5,1,0),"") | S35: =TEXT(B35,"yyyy-mm") -> 2026-03
A36: LA0032 | B36: 46040 | C36: Online | D36: DIGITAL | E36: 21000 | F36: 0 | G36: 46040 | H36: 46046 | I36: 46049 | K36: Approved | L36: =IF(OR(K36="Approved",K36="Declined"),1,0) -> 1 | M36: =IF(L36=1,I36-B36,"") -> 9 | N36: =IF(L36=1,G36-B36,"") -> 0 | O36: =IF(L36=1,H36-G36,"") -> 6 | P36: =IF(L36=1,I36-H36,"") -> 3 | Q36: =IF(K36="Open",Summary!$B$6-B36,"") | R36: =IF(L36=1,IF(M36<=Summary!$B$5,1,0),"") -> 0 | S36: =TEXT(B36,"yyyy-mm") -> 2026-01
A37: LA0033 | B37: 46057 | C37: Online | D37: DIGITAL | E37: 14000 | F37: 0 | G37: 46059 | H37: 46062 | I37: 46065 | K37: Declined | L37: =IF(OR(K37="Approved",K37="Declined"),1,0) -> 1 | M37: =IF(L37=1,I37-B37,"") -> 8 | N37: =IF(L37=1,G37-B37,"") -> 2 | O37: =IF(L37=1,H37-G37,"") -> 3 | P37: =IF(L37=1,I37-H37,"") -> 3 | Q37: =IF(K37="Open",Summary!$B$6-B37,"") | R37: =IF(L37=1,IF(M37<=Summary!$B$5,1,0),"") -> 0 | S37: =TEXT(B37,"yyyy-mm") -> 2026-02
A38: LA0034 | B38: 46090 | C38: Online | D38: DIGITAL | E38: 16000 | F38: 0 | G38: 46090 | H38: 46094 | I38: 46097 | K38: Approved | L38: =IF(OR(K38="Approved",K38="Declined"),1,0) -> 1 | M38: =IF(L38=1,I38-B38,"") -> 7 | N38: =IF(L38=1,G38-B38,"") -> 0 | O38: =IF(L38=1,H38-G38,"") -> 4 | P38: =IF(L38=1,I38-H38,"") -> 3 | Q38: =IF(K38="Open",Summary!$B$6-B38,"") | R38: =IF(L38=1,IF(M38<=Summary!$B$5,1,0),"") -> 1 | S38: =TEXT(B38,"yyyy-mm") -> 2026-03
A39: LA0035 | B39: 46112 | C39: Online | D39: DIGITAL | E39: 23000 | F39: 0 | G39: 46112 | K39: Open | L39: =IF(OR(K39="Approved",K39="Declined"),1,0) -> 0 | M39: =IF(L39=1,I39-B39,"") | N39: =IF(L39=1,G39-B39,"") | O39: =IF(L39=1,H39-G39,"") | P39: =IF(L39=1,I39-H39,"") | Q39: =IF(K39="Open",Summary!$B$6-B39,"") -> 0 | R39: =IF(L39=1,IF(M39<=Summary!$B$5,1,0),"") | S39: =TEXT(B39,"yyyy-mm") -> 2026-03
A40: LA0036 | B40: 46093 | C40: Online | D40: DIGITAL | E40: 28000 | F40: 0 | G40: 46094 | H40: 46097 | I40: 46098 | K40: Declined | L40: =IF(OR(K40="Approved",K40="Declined"),1,0) -> 1 | M40: =IF(L40=1,I40-B40,"") -> 5 | N40: =IF(L40=1,G40-B40,"") -> 1 | O40: =IF(L40=1,H40-G40,"") -> 3 | P40: =IF(L40=1,I40-H40,"") -> 1 | Q40: =IF(K40="Open",Summary!$B$6-B40,"") | R40: =IF(L40=1,IF(M40<=Summary!$B$5,1,0),"") -> 1 | S40: =TEXT(B40,"yyyy-mm") -> 2026-03
A41: LA0037 | B41: 46043 | C41: Online | D41: DIGITAL | E41: 14000 | F41: 1 | G41: 46051 | H41: 46054 | I41: 46055 | K41: Approved | L41: =IF(OR(K41="Approved",K41="Declined"),1,0) -> 1 | M41: =IF(L41=1,I41-B41,"") -> 12 | N41: =IF(L41=1,G41-B41,"") -> 8 | O41: =IF(L41=1,H41-G41,"") -> 3 | P41: =IF(L41=1,I41-H41,"") -> 1 | Q41: =IF(K41="Open",Summary!$B$6-B41,"") | R41: =IF(L41=1,IF(M41<=Summary!$B$5,1,0),"") -> 0 | S41: =TEXT(B41,"yyyy-mm") -> 2026-01
A42: LA0038 | B42: 46030 | C42: Branch | D42: B02 | E42: 35000 | F42: 1 | J42: 46032 | K42: Withdrawn | L42: =IF(OR(K42="Approved",K42="Declined"),1,0) -> 0 | M42: =IF(L42=1,I42-B42,"") | N42: =IF(L42=1,G42-B42,"") | O42: =IF(L42=1,H42-G42,"") | P42: =IF(L42=1,I42-H42,"") | Q42: =IF(K42="Open",Summary!$B$6-B42,"") | R42: =IF(L42=1,IF(M42<=Summary!$B$5,1,0),"") | S42: =TEXT(B42,"yyyy-mm") -> 2026-01
...

Sheet Raw
A2: Source: deterministic synthetic generator, seed 20261016. No employer or customer data.
A4: application_id | B4: submitted_date | C4: channel | D4: branch_id | E4: requested_amount | F4: missing_docs_at_intake | G4: document_ready_date | H4: review_start_date | I4: decision_date | J4: withdrawal_date | K4: status
A5: LA0001 | B5: 46040 | C5: online | D5: DIGITAL | E5: 16000 | F5: 0 | G5: 46042 | H5: 46046 | I5: 46049 | K5: Approved
A6: LA0002 | B6: 46035 | C6: online | D6: DIGITAL | E6: 15000 | F6: 0 | G6: 46037 | H6: 46039 | I6: 46042 | K6: Approved
A7: LA0003 | B7: 46103 | C7: online | D7: DIGITAL | E7: 43000 | F7: 0 | G7: 46105 | H7: 46106 | I7: 46109 | K7: Approved
A8: LA0004 | B8: 46083 | C8: branch | D8: B04 | E8: 12000 | F8: 0 | G8: 46085 | H8: 46088 | I8: 46091 | K8: Approved
A9: LA0005 | B9: 46078 | C9: online | D9: DIGITAL | E9: 6000 | F9: 0 | G9: 46080 | H9: 46085 | I9: 46086 | K9: Approved
A10: LA0006 | B10: 46083 | C10: branch | D10: B03 | E10: 38000 | F10: 0 | G10: 46083 | H10: 46087 | I10: 46089 | K10: Declined
A11: LA0007 | B11: 46092 | C11: branch | D11: B01 | E11: 13000 | F11: 0 | G11: 46093 | H11: 46097 | I11: 46099 | K11: Approved
A12: LA0008 | B12: 46038 | C12: branch | D12: B03 | E12: 43000 | F12: 0 | G12: 46040 | H12: 46043 | I12: 46045 | K12: Approved
A13: LA0009 | B13: 46103 | C13: branch | D13: B01 | E13: 29000 | F13: 1 | G13: 46107 | H13: 46110 | I13: 46111 | K13: Declined
A14: LA0010 | B14: 46110 | C14: online | D14: DIGITAL | E14: 12000 | F14: 0 | G14: 46110 | K14: Open
A15: LA0011 | B15: 46046 | C15: branch | D15: B02 | E15: 33000 | F15: 1 | G15: 46056 | H15: 46057 | I15: 46058 | K15: Declined
A16: LA0012 | B16: 46100 | C16: branch | D16: B04 | E16: 30000 | F16: 0 | G16: 46100 | H16: 46104 | I16: 46106 | K16: Declined
A17: LA0013 | B17: 46078 | C17: branch | D17: B03 | E17: 30000 | F17: 0 | G17: 46080 | H17: 46086 | I17: 46087 | K17: Approved
A18: LA0014 | B18: 46074 | C18: online | D18: DIGITAL | E18: 20000 | F18: 0 | G18: 46075 | H18: 46081 | I18: 46082 | K18: Declined
A19: LA0015 | B19: 46049 | C19: online | D19: DIGITAL | E19: 18000 | F19: 0 | G19: 46050 | H19: 46051 | I19: 46052 | K19: Approved
A20: LA0016 | B20: 46090 | C20: online | D20: DIGITAL | E20: 16000 | F20: 0 | G20: 46092 | H20: 46097 | I20: 46100 | K20: Approved
A21: LA0017 | B21: 46078 | C21: online | D21: DIGITAL | E21: 17000 | F21: 0 | G21: 46078 | H21: 46082 | I21: 46083 | K21: Approved
A22: LA0018 | B22: 46036 | C22: branch | D22: B03 | E22: 33000 | F22: 0 | G22: 46038 | H22: 46046 | I22: 46049 | K22: Approved
A23: LA0019 | B23: 46031 | C23: Online | D23: DIGITAL | E23: 32000 | F23: 1 | G23: 46039 | H23: 46045 | I23: 46047 | K23: Approved
A24: LA0020 | B24: 46093 | C24: Branch | D24: B04 | E24: 5000 | F24: 0 | G24: 46095 | H24: 46097 | I24: 46100 | K24: Approved
A25: LA0021 | B25: 46106 | C25: Branch | D25: B02 | E25: 28000 | F25: 0 | G25: 46107 | H25: 46110 | K25: Open
A26: LA0022 | B26: 46079 | C26: Online | D26: DIGITAL | E26: 44000 | F26: 0 | G26: 46081 | H26: 46083 | I26: 46085 | K26: Declined
A27: LA0023 | B27: 46101 | C27: Branch | D27: B04 | E27: 6000 | F27: 0 | G27: 46101 | H27: 46105 | I27: 46108 | K27: Approved
A28: LA0024 | B28: 46072 | C28: Online | D28: DIGITAL | E28: 11000 | F28: 0 | G28: 46073 | H28: 46077 | I28: 46079 | K28: Approved
A29: LA0025 | B29: 46069 | C29: Branch | D29: B04 | E29: 29000 | F29: 1 | J29: 46071 | K29: Withdrawn
A30: LA0026 | B30: 46036 | C30: Online | D30: DIGITAL | E30: 46000 | F30: 0 | G30: 46038 | H30: 46039 | I30: 46040 | K30: Approved
A31: LA0027 | B31: 46045 | C31: Online | D31: DIGITAL | E31: 12000 | F31: 0 | G31: 46047 | H31: 46053 | I31: 46056 | K31: Declined
A32: LA0028 | B32: 46052 | C32: Online | D32: DIGITAL | E32: 27000 | F32: 0 | G32: 46053 | H32: 46055 | I32: 46057 | K32: Declined
A33: LA0029 | B33: 46073 | C33: Branch | D33: B01 | E33: 11000 | F33: 1 | G33: 46077 | H33: 46082 | I33: 46085 | K33: Approved
A34: LA0030 | B34: 46073 | C34: Branch | D34: B04 | E34: 31000 | F34: 1 | G34: 46076 | H34: 46080 | I34: 46081 | K34: Approved
A35: LA0031 | B35: 46107 | C35: Online | D35: DIGITAL | E35: 24000 | F35: 0 | G35: 46108 | H35: 46112 | K35: Open
A36: LA0032 | B36: 46040 | C36: Online | D36: DIGITAL | E36: 21000 | F36: 0 | G36: 46040 | H36: 46046 | I36: 46049 | K36: Approved
A37: LA0033 | B37: 46057 | C37: Online | D37: DIGITAL | E37: 14000 | F37: 0 | G37: 46059 | H37: 46062 | I37: 46065 | K37: Declined
A38: LA0034 | B38: 46090 | C38: Online | D38: DIGITAL | E38: 16000 | F38: 0 | G38: 46090 | H38: 46094 | I38: 46097 | K38: Approved
A39: LA0035 | B39: 46112 | C39: Online | D39: DIGITAL | E39: 23000 | F39: 0 | G39: 46112 | K39: Open
A40: LA0036 | B40: 46093 | C40: Online | D40: DIGITAL | E40: 28000 | F40: 0 | G40: 46094 | H40: 46097 | I40: 46098 | K40: Declined
A41: LA0037 | B41: 46043 | C41: Online | D41: DIGITAL | E41: 14000 | F41: 1 | G41: 46051 | H41: 46054 | I41: 46055 | K41: Approved
A42: LA0038 | B42: 46030 | C42: Branch | D42: B02 | E42: 35000 | F42: 1 | J42: 46032 | K42: Withdrawn
...

Sheet Dictionary
A2: Field | B2: Meaning | C2: Type | D2: Missing value rule
A3: application_id | B3: Unique fictional application key | C3: Text | D3: Required
A4: submitted_date | B4: Application received, date grain | C4: Date | D4: Required
A5: channel | B5: Branch or Online after normalization | C5: Text | D5: Required
A6: branch_id | B6: B01 to B04 or DIGITAL | C6: Text | D6: Required
A7: requested_amount | B7: Requested principal in USD | C7: Number | D7: Required, positive
A8: missing_docs_at_intake | B8: 1 means documents missing at submission | C8: Integer | D8: Required, 0 or 1
A9: document_ready_date | B9: Document collection completed | C9: Date | D9: Blank if not reached or withdrawn
A10: review_start_date | B10: Underwriter review started | C10: Date | D10: Blank if not reached or withdrawn
A11: decision_date | B11: Approval or decline recorded | C11: Date | D11: Blank for open or withdrawn
A12: withdrawal_date | B12: Applicant withdrew before decision | C12: Date | D12: Only for withdrawn cases
A13: status | B13: Approved, Declined, Open, Withdrawn | C13: Text | D13: Required
... A21: submission_month | B21: Cohort month from submitted date | C21: Text YYYY-MM | D21: Required

Sheet Practice
A1: Document collection days | B1: Review queue days | C1: Underwriting review days | D1: Total decision days | E1: Time check
A2: =Applications!G5-Applications!B5 -> 2 | B2: =Applications!H5-Applications!G5 -> 4 | C2: =Applications!I5-Applications!H5 -> 3 | D2: =Applications!I5-Applications!B5 -> 9 | E2: =IF(SUM(A2:C2)=D2,"Match","Check") -> Match
A5: Average document days | B5: Average queue days | C5: Average review days | D5: Average total days
A6: =AVERAGE(Applications!N5:N604) -> 2.6059406 | B6: =AVERAGE(Applications!O5:O604) -> 3.9207921 | C6: =AVERAGE(Applications!P5:P604) -> 2.0158416 | D6: =AVERAGE(Applications!M5:M604) -> 8.5425743
A8: Queue share of total time
A9: =B6/D6 -> 0.45897079
A11: Branch | B11: Average queue days | C11: Completed decisions
A12: B01 | B12: =AVERAGEIFS(Applications!$O$5:$O$604,Applications!$D$5:$D$604,A12,Applications!$L$5:$L$604,1) -> 3.3846154 | C12: =COUNTIFS(Applications!$D$5:$D$604,A12,Applications!$L$5:$L$604,1) -> 78
A13: B02 | B13: =AVERAGEIFS(Applications!$O$5:$O$604,Applications!$D$5:$D$604,A13,Applications!$L$5:$L$604,1) -> 3.295082 | C13: =COUNTIFS(Applications!$D$5:$D$604,A13,Applications!$L$5:$L$604,1) -> 61
A14: B03 | B14: =AVERAGEIFS(Applications!$O$5:$O$604,Applications!$D$5:$D$604,A14,Applications!$L$5:$L$604,1) -> 5.6805556 | C14: =COUNTIFS(Applications!$D$5:$D$604,A14,Applications!$L$5:$L$604,1) -> 72
A15: B04 | B15: =AVERAGEIFS(Applications!$O$5:$O$604,Applications!$D$5:$D$604,A15,Applications!$L$5:$L$604,1) -> 4.0857143 | C15: =COUNTIFS(Applications!$D$5:$D$604,A15,Applications!$L$5:$L$604,1) -> 70
A18: Missing documents at intake | B18: Average total decision days | C18: Completed decisions
A19: 0 | B19: =AVERAGEIFS(Applications!$M$5:$M$604,Applications!$F$5:$F$604,A19,Applications!$L$5:$L$604,1) -> 6.9660057 | C19: =COUNTIFS(Applications!$F$5:$F$604,A19,Applications!$L$5:$L$604,1) -> 353
A20: 1 | B20: =AVERAGEIFS(Applications!$M$5:$M$604,Applications!$F$5:$F$604,A20,Applications!$L$5:$L$604,1) -> 12.203947 | C20: =COUNTIFS(Applications!$F$5:$F$604,A20,Applications!$L$5:$L$604,1) -> 152
A22: Difference in days | B22: =B20-B19 -> 5.2379417
A24: Decisions within 7 days | B24: =COUNTIFS(Applications!$L$5:$L$604,1,Applications!$M$5:$M$604,"<=7")/COUNTIFS(Applications!$L$5:$L$604,1) -> 0.42970297
A25: Completed decisions | B25: =COUNTIFS(Applications!$L$5:$L$604,1) -> 505
A26: Open applications | B26: =COUNTIFS(Applications!$K$5:$K$604,"Open") -> 61
A27: Withdrawn applications | B27: =COUNTIFS(Applications!$K$5:$K$604,"Withdrawn") -> 34
A28: Open applications older than 7 days | B28: =COUNTIFS(Applications!$K$5:$K$604,"Open",Applications!$Q$5:$Q$604,">7") -> 8
A29: Share of open applications older than 7 days | B29: =B28/B26 -> 0.13114754

Sheet Requirements
A1: Requirement ID | B1: Requirement | C1: Acceptance criterion 1 | D1: Acceptance criterion 2
A2: FR01 | B2: The system must check that all required documents are present before allowing an application into the review queue. | C2: Block the move, display the missing documents, and keep the application in Awaiting documents status. | D2: Allow the application into the review queue and record the document completion date and time.
A3: FR02 | B3: The system must display applications awaiting review in a shared queue with an assigned reviewer and elapsed queue days. | C3: When a document complete application enters the queue, display its application ID, queue entry date, reviewer or Unassigned, and elapsed queue days. Calculate elapsed queue days as the current date minus the queue entry date. | D3: When a loan manager assigns or changes the reviewer, the queue displays the new owner and records who made the change and when.
A4: FR03 | B4: The system must flag active applications older than 7 calendar days since submission for follow up. | C4: At the daily refresh, an active application aged 8 days is flagged. An application aged exactly 7 days is not flagged. | D4: Approved, declined, and withdrawn applications are excluded from the active follow up list. Each flagged application displays its owner or Unassigned.

Sheet UAT_Plan
A1: Test ID | B1: Requirement ID | C1: Scenario and action | D1: Expected result | E1: Test status
A2: UAT01 | B2: FR01 | C2: Try moving an application with one required document missing into review. | D2: Move is blocked, the missing document is listed, and status remains Awaiting documents. | E2: Not run
A3: UAT02 | B3: FR01 | C3: Provide all required documents and move the application into review. | D3: Move is allowed and the document completion date and time are recorded. | E3: Not run
A4: UAT03 | B4: FR02 | C4: View an unassigned application that entered the review queue 3 calendar days ago. | D4: Application appears with its ID, queue entry date, Unassigned label, and 3 elapsed queue days. | E4: Not run
A5: UAT04 | B5: FR02 | C5: As a loan manager, change an application's reviewer from Officer A to Officer B. | D5: Queue displays Officer B and records the manager who made the change and its date and time. | E5: Not run
A6: UAT05 | B6: FR03 | C6: Run the daily refresh for an active application exactly 7 calendar days old. | D6: Application is not flagged. | E6: Not run
A7: UAT06 | B7: FR03 | C7: Run the daily refresh for an active application 8 calendar days old. | D7: Application is flagged and displays its owner or Unassigned. | E7: Not run
A8: UAT07 | B8: FR03 | C8: Run the daily refresh with approved, declined, and withdrawn applications each 8 days old. | D8: All three applications are excluded from the active follow up list. | E8: Not run

Sheet Traceability
A1: Business problem | B1: Supporting finding | C1: Requirement ID | D1: Proposed change | E1: Test IDs
A2: Missing documents | B2: Completed applications with missing documents averaged 12.20 days versus 6.97 without. | C2: FR01 | D2: Check document completeness before entry into review. | E2: UAT01, UAT02
A3: Waiting for review | B3: Average queue time was 3.92 days overall. B03 averaged 5.68 days. | C3: FR02 | D3: Show a shared review queue with ownership and elapsed queue days. | E3: UAT03, UAT04
A4: Applications needing follow up | B4: 8 of 61 open applications were older than 7 days at March 31, 2026. | C4: FR03 | D4: Flag active applications older than 7 calendar days. | E4: UAT05, UAT06, UAT07

Sheet Proposed_Process

Sheet KPI_Plan
A1: KPI | B1: Baseline | C1: Proposed target | D1: How to measure
A2: Average loan decision time | B2: 8.54 calendar days | C2: 7.00 calendar days or less | D2: Average days from submission to decision for approved and declined applications
A3: Average review queue time | B3: 3.92 calendar days | C3: 3.00 calendar days or less | D3: Average days from document completion to review start for approved and declined applications
A4: Applications missing documents at intake | B4: 0.348 | C4: 25.0% or less | D4: Applications missing required documents at initial submission divided by all submitted applications
A5: Decisions completed within 7 days | B5: 0.43 | C5: 60.0% or more | D5: Approved and declined applications decided within 7 calendar days divided by all approved and declined applications
A7: Evaluation plan: Propose a four week pilot using the document checklist, shared review queue and daily follow up flags. Compare the KPIs with the baseline using the same definitions. Also track open applications and their age so unfinished cases are not hidden.
A9: Target assumptions: These are illustrative targets for discussion with stakeholders. They have not been approved or achieved.
A11: Portfolio limitation: No operational pilot was conducted. The baseline comes from synthetic data, and the proposed benefits remain untested.
